2025-04-01 20:46:35 - uvicorn.error - INFO - [server.py:83] Started server process [26]
2025-04-01 20:46:35 - uvicorn.error - INFO - [on.py:48] Waiting for application startup.
2025-04-01 20:46:35 - src.main - INFO - [main.py:35] Iniciando o sistema...
2025-04-01 20:46:35 - src.db.database - INFO - [database.py:38] Iniciando conexão com o banco de dados...
2025-04-01 20:46:35 - src.db.database - INFO - [database.py:42] Conexão com o banco de dados estabelecida com sucesso.
2025-04-01 20:46:35 - src.main - INFO - [main.py:37] Sistema iniciado com sucesso.
2025-04-01 20:46:35 - uvicorn.error - INFO - [on.py:62] Application startup complete.
2025-04-01 20:46:58 - uvicorn.access - INFO - [httptools_impl.py:476] 172.19.0.1:47184 - "GET /docs HTTP/1.1" 200
2025-04-01 20:46:58 - uvicorn.access - INFO - [httptools_impl.py:476] 172.19.0.1:47184 - "GET /openapi.json HTTP/1.1" 200
2025-04-01 20:47:02 - uvicorn.access - INFO - [httptools_impl.py:476] 172.19.0.1:47184 - "POST /pessoa/ HTTP/1.1" 500
2025-04-01 20:47:02 - uvicorn.error - ERROR - [httptools_impl.py:414] Exception in ASGI application
Traceback (most recent call last):
  File "/usr/local/lib/python3.11/site-packages/sqlalchemy/engine/base.py", line 1964, in _exec_single_context
    self.dialect.do_execute(
  File "/usr/local/lib/python3.11/site-packages/sqlalchemy/engine/default.py", line 942, in do_execute
    cursor.execute(statement, parameters)
  File "/usr/local/lib/python3.11/site-packages/sqlalchemy/dialects/mysql/aiomysql.py", line 97, in execute
    return self.await_(self._execute_async(operation, parameters))
           ^^^^^^^^^^^^^^^^^^^^^^^^^^^^^^^^^^^^^^^^^^^^^^^^^^^^^^^
  File "/usr/local/lib/python3.11/site-packages/sqlalchemy/util/_concurrency_py3k.py", line 132, in await_only
    return current.parent.switch(awaitable)  # type: ignore[no-any-return,attr-defined] # noqa: E501
           ^^^^^^^^^^^^^^^^^^^^^^^^^^^^^^^^
  File "/usr/local/lib/python3.11/site-packages/sqlalchemy/util/_concurrency_py3k.py", line 196, in greenlet_spawn
    value = await result
            ^^^^^^^^^^^^
  File "/usr/local/lib/python3.11/site-packages/sqlalchemy/dialects/mysql/aiomysql.py", line 106, in _execute_async
    result = await self._cursor.execute(operation, parameters)
             ^^^^^^^^^^^^^^^^^^^^^^^^^^^^^^^^^^^^^^^^^^^^^^^^^
  File "/usr/local/lib/python3.11/site-packages/aiomysql/cursors.py", line 239, in execute
    await self._query(query)
  File "/usr/local/lib/python3.11/site-packages/aiomysql/cursors.py", line 457, in _query
    await conn.query(q)
  File "/usr/local/lib/python3.11/site-packages/aiomysql/connection.py", line 469, in query
    await self._read_query_result(unbuffered=unbuffered)
  File "/usr/local/lib/python3.11/site-packages/aiomysql/connection.py", line 683, in _read_query_result
    await result.read()
  File "/usr/local/lib/python3.11/site-packages/aiomysql/connection.py", line 1164, in read
    first_packet = await self.connection._read_packet()
                   ^^^^^^^^^^^^^^^^^^^^^^^^^^^^^^^^^^^^
  File "/usr/local/lib/python3.11/site-packages/aiomysql/connection.py", line 652, in _read_packet
    packet.raise_for_error()
  File "/usr/local/lib/python3.11/site-packages/pymysql/protocol.py", line 219, in raise_for_error
    err.raise_mysql_exception(self._data)
  File "/usr/local/lib/python3.11/site-packages/pymysql/err.py", line 150, in raise_mysql_exception
    raise errorclass(errno, errval)
pymysql.err.ProgrammingError: (1146, "Table 'database.pessoas' doesn't exist")

The above exception was the direct cause of the following exception:

Traceback (most recent call last):
  File "/usr/local/lib/python3.11/site-packages/uvicorn/protocols/http/httptools_impl.py", line 409, in run_asgi
    result = await app(  # type: ignore[func-returns-value]
             ^^^^^^^^^^^^^^^^^^^^^^^^^^^^^^^^^^^^^^^^^^^^^^
  File "/usr/local/lib/python3.11/site-packages/uvicorn/middleware/proxy_headers.py", line 60, in __call__
    return await self.app(scope, receive, send)
           ^^^^^^^^^^^^^^^^^^^^^^^^^^^^^^^^^^^^
  File "/usr/local/lib/python3.11/site-packages/fastapi/applications.py", line 1054, in __call__
    await super().__call__(scope, receive, send)
  File "/usr/local/lib/python3.11/site-packages/starlette/applications.py", line 112, in __call__
    await self.middleware_stack(scope, receive, send)
  File "/usr/local/lib/python3.11/site-packages/starlette/middleware/errors.py", line 187, in __call__
    raise exc
  File "/usr/local/lib/python3.11/site-packages/starlette/middleware/errors.py", line 165, in __call__
    await self.app(scope, receive, _send)
  File "/usr/local/lib/python3.11/site-packages/starlette/middleware/cors.py", line 93, in __call__
    await self.simple_response(scope, receive, send, request_headers=headers)
  File "/usr/local/lib/python3.11/site-packages/starlette/middleware/cors.py", line 144, in simple_response
    await self.app(scope, receive, send)
  File "/usr/local/lib/python3.11/site-packages/starlette/middleware/exceptions.py", line 62, in __call__
    await wrap_app_handling_exceptions(self.app, conn)(scope, receive, send)
  File "/usr/local/lib/python3.11/site-packages/starlette/_exception_handler.py", line 53, in wrapped_app
    raise exc
  File "/usr/local/lib/python3.11/site-packages/starlette/_exception_handler.py", line 42, in wrapped_app
    await app(scope, receive, sender)
  File "/usr/local/lib/python3.11/site-packages/starlette/routing.py", line 715, in __call__
    await self.middleware_stack(scope, receive, send)
  File "/usr/local/lib/python3.11/site-packages/starlette/routing.py", line 735, in app
    await route.handle(scope, receive, send)
  File "/usr/local/lib/python3.11/site-packages/starlette/routing.py", line 288, in handle
    await self.app(scope, receive, send)
  File "/usr/local/lib/python3.11/site-packages/starlette/routing.py", line 76, in app
    await wrap_app_handling_exceptions(app, request)(scope, receive, send)
  File "/usr/local/lib/python3.11/site-packages/starlette/_exception_handler.py", line 53, in wrapped_app
    raise exc
  File "/usr/local/lib/python3.11/site-packages/starlette/_exception_handler.py", line 42, in wrapped_app
    await app(scope, receive, sender)
  File "/usr/local/lib/python3.11/site-packages/starlette/routing.py", line 73, in app
    response = await f(request)
               ^^^^^^^^^^^^^^^^
  File "/usr/local/lib/python3.11/site-packages/fastapi/routing.py", line 301, in app
    raw_response = await run_endpoint_function(
                   ^^^^^^^^^^^^^^^^^^^^^^^^^^^^
  File "/usr/local/lib/python3.11/site-packages/fastapi/routing.py", line 212, in run_endpoint_function
    return await dependant.call(**values)
           ^^^^^^^^^^^^^^^^^^^^^^^^^^^^^^
  File "/app/src/api/v1/pessoa.py", line 20, in cria_pessoa
    existing_pessoa = await PessoaRepository.get_by_cpf_cnpj(db, pessoaSchema.cpf_cnpj)
                      ^^^^^^^^^^^^^^^^^^^^^^^^^^^^^^^^^^^^^^^^^^^^^^^^^^^^^^^^^^^^^^^^^
  File "/app/src/repositories/pessoa_repository.py", line 45, in get_by_cpf_cnpj
    result = await db.execute(query)
             ^^^^^^^^^^^^^^^^^^^^^^^
  File "/usr/local/lib/python3.11/site-packages/sqlalchemy/ext/asyncio/session.py", line 463, in execute
    result = await greenlet_spawn(
             ^^^^^^^^^^^^^^^^^^^^^
  File "/usr/local/lib/python3.11/site-packages/sqlalchemy/util/_concurrency_py3k.py", line 201, in greenlet_spawn
    result = context.throw(*sys.exc_info())
             ^^^^^^^^^^^^^^^^^^^^^^^^^^^^^^
  File "/usr/local/lib/python3.11/site-packages/sqlalchemy/orm/session.py", line 2365, in execute
    return self._execute_internal(
           ^^^^^^^^^^^^^^^^^^^^^^^
  File "/usr/local/lib/python3.11/site-packages/sqlalchemy/orm/session.py", line 2251, in _execute_internal
    result: Result[Any] = compile_state_cls.orm_execute_statement(
                          ^^^^^^^^^^^^^^^^^^^^^^^^^^^^^^^^^^^^^^^^
  File "/usr/local/lib/python3.11/site-packages/sqlalchemy/orm/context.py", line 305, in orm_execute_statement
    result = conn.execute(
             ^^^^^^^^^^^^^
  File "/usr/local/lib/python3.11/site-packages/sqlalchemy/engine/base.py", line 1416, in execute
    return meth(
           ^^^^^
  File "/usr/local/lib/python3.11/site-packages/sqlalchemy/sql/elements.py", line 515, in _execute_on_connection
    return connection._execute_clauseelement(
           ^^^^^^^^^^^^^^^^^^^^^^^^^^^^^^^^^^
  File "/usr/local/lib/python3.11/site-packages/sqlalchemy/engine/base.py", line 1638, in _execute_clauseelement
    ret = self._execute_context(
          ^^^^^^^^^^^^^^^^^^^^^^
  File "/usr/local/lib/python3.11/site-packages/sqlalchemy/engine/base.py", line 1843, in _execute_context
    return self._exec_single_context(
           ^^^^^^^^^^^^^^^^^^^^^^^^^^
  File "/usr/local/lib/python3.11/site-packages/sqlalchemy/engine/base.py", line 1983, in _exec_single_context
    self._handle_dbapi_exception(
  File "/usr/local/lib/python3.11/site-packages/sqlalchemy/engine/base.py", line 2352, in _handle_dbapi_exception
    raise sqlalchemy_exception.with_traceback(exc_info[2]) from e
  File "/usr/local/lib/python3.11/site-packages/sqlalchemy/engine/base.py", line 1964, in _exec_single_context
    self.dialect.do_execute(
  File "/usr/local/lib/python3.11/site-packages/sqlalchemy/engine/default.py", line 942, in do_execute
    cursor.execute(statement, parameters)
  File "/usr/local/lib/python3.11/site-packages/sqlalchemy/dialects/mysql/aiomysql.py", line 97, in execute
    return self.await_(self._execute_async(operation, parameters))
           ^^^^^^^^^^^^^^^^^^^^^^^^^^^^^^^^^^^^^^^^^^^^^^^^^^^^^^^
  File "/usr/local/lib/python3.11/site-packages/sqlalchemy/util/_concurrency_py3k.py", line 132, in await_only
    return current.parent.switch(awaitable)  # type: ignore[no-any-return,attr-defined] # noqa: E501
           ^^^^^^^^^^^^^^^^^^^^^^^^^^^^^^^^
  File "/usr/local/lib/python3.11/site-packages/sqlalchemy/util/_concurrency_py3k.py", line 196, in greenlet_spawn
    value = await result
            ^^^^^^^^^^^^
  File "/usr/local/lib/python3.11/site-packages/sqlalchemy/dialects/mysql/aiomysql.py", line 106, in _execute_async
    result = await self._cursor.execute(operation, parameters)
             ^^^^^^^^^^^^^^^^^^^^^^^^^^^^^^^^^^^^^^^^^^^^^^^^^
  File "/usr/local/lib/python3.11/site-packages/aiomysql/cursors.py", line 239, in execute
    await self._query(query)
  File "/usr/local/lib/python3.11/site-packages/aiomysql/cursors.py", line 457, in _query
    await conn.query(q)
  File "/usr/local/lib/python3.11/site-packages/aiomysql/connection.py", line 469, in query
    await self._read_query_result(unbuffered=unbuffered)
  File "/usr/local/lib/python3.11/site-packages/aiomysql/connection.py", line 683, in _read_query_result
    await result.read()
  File "/usr/local/lib/python3.11/site-packages/aiomysql/connection.py", line 1164, in read
    first_packet = await self.connection._read_packet()
                   ^^^^^^^^^^^^^^^^^^^^^^^^^^^^^^^^^^^^
  File "/usr/local/lib/python3.11/site-packages/aiomysql/connection.py", line 652, in _read_packet
    packet.raise_for_error()
  File "/usr/local/lib/python3.11/site-packages/pymysql/protocol.py", line 219, in raise_for_error
    err.raise_mysql_exception(self._data)
  File "/usr/local/lib/python3.11/site-packages/pymysql/err.py", line 150, in raise_mysql_exception
    raise errorclass(errno, errval)
sqlalchemy.exc.ProgrammingError: (pymysql.err.ProgrammingError) (1146, "Table 'database.pessoas' doesn't exist")
[SQL: SELECT pessoas.id, pessoas.tipo, pessoas.sexo, pessoas.nome, pessoas.sobrenome, pessoas.endereco, pessoas.bairro, pessoas.cidade, pessoas.cep, pessoas.numero, pessoas.data_nascimento, pessoas.cpf_cnpj, pessoas.rg_ie, pessoas.data_criacao, pessoas.data_atualizacao, pessoas.`Admin` 
FROM pessoas 
WHERE pessoas.cpf_cnpj = %s]
[parameters: ('string',)]
(Background on this error at: https://sqlalche.me/e/20/f405)
2025-04-01 20:47:08 - uvicorn.error - INFO - [server.py:263] Shutting down
2025-04-01 20:47:08 - uvicorn.error - INFO - [on.py:67] Waiting for application shutdown.
2025-04-01 20:47:08 - src.main - INFO - [main.py:44] Encerrando o sistema...
2025-04-01 20:47:08 - uvicorn.error - INFO - [on.py:76] Application shutdown complete.
2025-04-01 20:47:08 - uvicorn.error - INFO - [server.py:93] Finished server process [26]
2025-04-01 20:47:30 - uvicorn.error - INFO - [server.py:83] Started server process [38]
2025-04-01 20:47:30 - uvicorn.error - INFO - [on.py:48] Waiting for application startup.
2025-04-01 20:47:30 - src.main - INFO - [main.py:35] Iniciando o sistema...
2025-04-01 20:47:30 - src.db.database - INFO - [database.py:38] Iniciando conexão com o banco de dados...
2025-04-01 20:47:30 - src.db.database - INFO - [database.py:42] Conexão com o banco de dados estabelecida com sucesso.
2025-04-01 20:47:30 - src.main - INFO - [main.py:37] Sistema iniciado com sucesso.
2025-04-01 20:47:30 - uvicorn.error - INFO - [on.py:62] Application startup complete.
2025-04-01 20:47:34 - uvicorn.access - INFO - [httptools_impl.py:476] 172.19.0.1:56874 - "POST /pessoa/ HTTP/1.1" 201
2025-04-01 20:47:42 - uvicorn.access - INFO - [httptools_impl.py:476] 172.19.0.1:54696 - "PUT /pessoa/1 HTTP/1.1" 201
